<?xml version="1.0"?>
<robot name="ultron" xmlns:xacro="http://www.ros.org/wiki/xacro">

    <joint name="chassis_joint" type="fixed">
        <parent link="base_link" />
        <child link="chassis_link" />
        <origin xyz="0.0 0.0 0.0" rpy="0.0 0.0 0.0" />
    </joint>

    <joint name="left_wheel_joint" type="continuous">
        <origin xyz="-0.09 0.1625 0.015" rpy="0.0 0.0 0.0" />
        <parent link="chassis_link" />
        <child link="left_wheel_link" />
        <axis xyz="0.0 1.0 0.0"/>
    </joint>

    <joint name="right_wheel_joint" type="continuous">
        <origin xyz="-0.09 -0.1625 0.015" rpy="0.0 0.0 0.0" />
        <parent link="chassis_link" />
        <child link="right_wheel_link" />
        <axis xyz="0.0 1.0 0.0"/>
    </joint>

    <joint name="caster_joint" type="fixed">
        <origin xyz="0.10 0.0 0.0" rpy="0.0 0.0 0.0" />
        <parent link="chassis_link" />
        <child link="caster_link" />
    </joint>

    <joint name="lidar_joint" type="fixed">
        <origin xyz="0.0 0.0 0.06" rpy="0.0 0.0 0.0"/>
        <parent link="chassis_link"/>
        <child link="lidar_link"/>
    </joint>

</robot>